#VRML_SIM R2020a utf8
WorldInfo {
}
Viewpoint {
  orientation -0.9968593441767543 -0.07603883987766809 -0.02212561315647646 0.7729758147643394
  position -0.8046567502068651 3.101188439862809 3.3201321305345313
}
TexturedBackground {
}
TexturedBackgroundLight {
}
DEF area RectangleArena {
  translation -0.257628 0 -0.192172
  floorSize 1.83 1.83
  floorTileSize 0.914 0.914
}
WoodenBox {
  translation -0.715972 0 -0.652664
  name "wooden box(1)"
  size 0.914 0.2 0.01
}
DEF YellowCylinder Solid {
  translation -1.05027 0.2 -1.02641
  rotation 1.92079e-07 -1 1.10737e-06 1.30899
  children [
    DEF landmark Shape {
      appearance PBRAppearance {
        baseColor 1 1 0
        roughness 1
        metalness 0
      }
      geometry Cylinder {
        height 0.7
        radius 0.12
      }
    }
  ]
  boundingObject USE landmark
  physics DEF landmarkPH Physics {
  }
  recognitionColors [
    0 0 1
  ]
}
WoodenBox {
  translation -0.253634 0 0.259886
  name "wooden box(2)"
  size 0.914 0.2 0.01
}
WoodenBox {
  translation 0.201435 0 -0.196602
  rotation 0 1 0 -1.5707953071795862
  name "wooden box(3)"
  size 0.914 0.2 0.01
}
WoodenBox {
  translation -0.71079 0 0.0332991
  rotation 0 1 0 -1.5707953071795862
  name "wooden box(4)"
  size 0.4572 0.2 0.01
}
DEF epuck E-puck {
  translation 0.46465 1.77636e-15 0.502407
  rotation -4.9580396042433186e-06 -0.9999999201788042 0.0003995219681096762 -1.5707853071795865
  controller "lab2_task5"
  supervisor TRUE
  camera_width 50
  turretSlot [
    InertialUnit {
      rotation 0 1 0 3.14
    }
    DEF righthinge HingeJoint {
      jointParameters HingeJointParameters {
        axis -1 0 0
        anchor 0 0.025 0
      }
      device [
        RotationalMotor {
          name "right wheel motor"
          consumptionFactor 70
          controlPID 8 2 0.5
        }
        PositionSensor {
          name "right wheel sensor"
        }
      ]
      endPoint Solid {
        translation 0.045009957783801 0.025013380758883635 -2.4671929852070224e-05
        rotation 0.9999993203499804 0.0010052734270078172 -0.0005905293508524929 4.6368371220546685
        children [
          DEF WHEEL Transform {
            translation -0.007 0.01 -0.05
            rotation 0 0 1 1.57
            children [
              Shape {
                appearance PBRAppearance {
                  baseColor 0 0 0
                  transparency 1
                  roughness 1
                  metalness 0
                }
                geometry Cylinder {
                  height 0.01
                  radius 0.02
                }
              }
            ]
            rotationStep 0.25
          }
        ]
        name "right wheel(1)"
        boundingObject USE WHEEL
        physics DEF PHYSICS_WHEEL Physics {
          density -1
          mass 0.05
        }
        rotationStep 0.25
      }
    }
    DEF lefthinge HingeJoint {
      jointParameters HingeJointParameters {
        axis -1 0 0
        anchor 0 0.025 0
      }
      device [
        RotationalMotor {
          name "left wheel motor"
          consumptionFactor 70
          controlPID 8 0 0
        }
        PositionSensor {
          name "left wheel sensor"
        }
      ]
      endPoint Solid {
        translation -0.04501012942703837 0.024977671977279067 -4.5733976162035045e-05
        rotation -0.9999982113395168 0.00047275268613733115 -0.0018313444964861228 1.2425810202889573
        children [
          DEF WHEEL Transform {
            translation 0.007 0 -0.05
            rotation 0 0 1 1.57
            children [
              Shape {
                appearance PBRAppearance {
                  baseColor 0.1 0.1 0.1
                  transparency 1
                  roughness 1
                  metalness 0
                }
                geometry Cylinder {
                  height 0.01
                  radius 0.02
                }
              }
            ]
            rotationStep 0.25
          }
        ]
        name "left wheel(1)"
        boundingObject USE WHEEL
        physics DEF PHYSICS_WHEEL Physics {
          density -1
          mass 0.05
        }
      }
    }
    DEF front_ds DistanceSensor {
      translation 0 0 -0.045
      rotation 0 1 0 1.5708
      name "front_ds"
      recognitionColors [
        0 0 0
      ]
      lookupTable [
        0 0 0
        1.27 1.27 0
      ]
    }
    DEF right_ds DistanceSensor {
      translation 0.035 -0.01 -0.01
      name "right_ds"
      lookupTable [
        0 0 0
        1.27 1.27 0
      ]
    }
    DEF left_ds DistanceSensor {
      translation -0.035 -0.01 -0.01
      rotation 0 1 0 3.14159
      name "left_ds"
      lookupTable [
        0 0 0
        1.27 1.27 0
      ]
    }
    Camera {
      translation 0 -0.01 -0.045
      name "camera1"
      recognitionColors [
        1 1 0
      ]
      fieldOfView 1.57
      width 80
      height 80
      recognition Recognition {
      }
    }
  ]
}
